<sdf version='1.7'>
  <world name='default'>
    <light name='sun' type='directional'>
      <cast_shadows>1</cast_shadows>
      <pose>0 0 10 0 -0 0</pose>
      <diffuse>0.8 0.8 0.8 1</diffuse>
      <specular>0.2 0.2 0.2 1</specular>
      <attenuation>
        <range>1000</range>
        <constant>0.9</constant>
        <linear>0.01</linear>
        <quadratic>0.001</quadratic>
      </attenuation>
      <direction>-0.5 0.1 -0.9</direction>
      <spot>
        <inner_angle>0</inner_angle>
        <outer_angle>0</outer_angle>
        <falloff>0</falloff>
      </spot>
    </light>
    <model name='ground_plane'>
      <static>1</static>
      <link name='link'>
        <collision name='collision'>
          <geometry>
            <plane>
              <normal>0 0 1</normal>
              <size>100 100</size>
            </plane>
          </geometry>
          <surface>
            <contact>
              <collide_bitmask>65535</collide_bitmask>
              <ode/>
            </contact>
            <friction>
              <ode>
                <mu>100</mu>
                <mu2>50</mu2>
              </ode>
              <torsional>
                <ode/>
              </torsional>
            </friction>
            <bounce/>
          </surface>
          <max_contacts>10</max_contacts>
        </collision>
        <visual name='visual'>
          <cast_shadows>0</cast_shadows>
          <geometry>
            <plane>
              <normal>0 0 1</normal>
              <size>100 100</size>
            </plane>
          </geometry>
          <material>
            <script>
              <uri>file://media/materials/scripts/gazebo.material</uri>
              <name>Gazebo/Grey</name>
            </script>
          </material>
        </visual>
        <self_collide>0</self_collide>
        <enable_wind>0</enable_wind>
        <kinematic>0</kinematic>
      </link>
    </model>
    <gravity>0 0 -9.8</gravity>
    <magnetic_field>6e-06 2.3e-05 -4.2e-05</magnetic_field>
    <atmosphere type='adiabatic'/>
    <physics type='ode'>
      <max_step_size>0.001</max_step_size>
      <real_time_factor>1</real_time_factor>
      <real_time_update_rate>1000</real_time_update_rate>
    </physics>
    <scene>
      <ambient>0.4 0.4 0.4 1</ambient>
      <background>0.7 0.7 0.7 1</background>
      <shadows>1</shadows>
    </scene>
    <audio>
      <device>default</device>
    </audio>
    <wind/>
    <spherical_coordinates>
      <surface_model>EARTH_WGS84</surface_model>
      <latitude_deg>0</latitude_deg>
      <longitude_deg>0</longitude_deg>
      <elevation>0</elevation>
      <heading_deg>0</heading_deg>
    </spherical_coordinates>
    <model name='ur'>
      <joint name='base_joint' type='fixed'>
        <pose relative_to='__model__'>0 0 0.35 0 -0 0</pose>
        <parent>world</parent>
        <child>base_link</child>
      </joint>
      <link name='base_link'>
        <pose relative_to='base_joint'>0 0 0 0 -0 0</pose>
        <inertial>
          <pose>0 0 0 0 -0 0</pose>
          <mass>4</mass>
          <inertia>
            <ixx>0.00610633</ixx>
            <ixy>0</ixy>
            <ixz>0</ixz>
            <iyy>0.00610633</iyy>
            <iyz>0</iyz>
            <izz>0.01125</izz>
          </inertia>
        </inertial>
        <collision name='base_link_inertia_collision'>
          <pose>0 0 0 0 -0 0</pose>
          <geometry>
            <mesh>
              <scale>1 1 1</scale>
              <uri>file:///root/ros2_ws/install/ur_description/share/ur_description/meshes/ur10e/collision/base.stl</uri>
            </mesh>
          </geometry>
          <max_contacts>10</max_contacts>
          <surface>
            <contact>
              <ode/>
            </contact>
            <bounce/>
            <friction>
              <torsional>
                <ode/>
              </torsional>
              <ode/>
            </friction>
          </surface>
        </collision>
        <visual name='base_link_inertia_visual'>
          <pose>0 0 0 0 -0 0</pose>
          <geometry>
            <mesh>
              <scale>1 1 1</scale>
              <uri>file:///root/ros2_ws/install/ur_description/share/ur_description/meshes/ur10e/visual/base.dae</uri>
            </mesh>
          </geometry>
        </visual>
        <self_collide>0</self_collide>
        <enable_wind>0</enable_wind>
        <kinematic>0</kinematic>
      </link>
      <joint name='shoulder_pan_joint' type='revolute'>
        <pose relative_to='base_link'>0 0 0.1807 0 -0 3.14159</pose>
        <parent>base_link</parent>
        <child>shoulder_link</child>
        <axis>
          <xyz>0 0 1</xyz>
          <limit>
            <lower>-6.28319</lower>
            <upper>6.28319</upper>
            <effort>330</effort>
            <velocity>2.0944</velocity>
          </limit>
          <dynamics>
            <damping>0</damping>
            <friction>0</friction>
            <spring_reference>0</spring_reference>
            <spring_stiffness>0</spring_stiffness>
          </dynamics>
        </axis>
      </joint>
      <link name='shoulder_link'>
        <pose relative_to='shoulder_pan_joint'>0 0 0 0 -0 0</pose>
        <inertial>
          <pose>0 -0.03 -0.016 1.5708 -0 0</pose>
          <mass>7.369</mass>
          <inertia>
            <ixx>0.03351</ixx>
            <ixy>2e-05</ixy>
            <ixz>-1e-05</ixz>
            <iyy>0.03374</iyy>
            <iyz>0.00374</iyz>
            <izz>0.021</izz>
          </inertia>
        </inertial>
        <collision name='shoulder_link_collision'>
          <pose>0 0 0 0 -0 3.14159</pose>
          <geometry>
            <mesh>
              <scale>1 1 1</scale>
              <uri>file:///root/ros2_ws/install/ur_description/share/ur_description/meshes/ur10e/collision/shoulder.stl</uri>
            </mesh>
          </geometry>
          <max_contacts>10</max_contacts>
          <surface>
            <contact>
              <ode/>
            </contact>
            <bounce/>
            <friction>
              <torsional>
                <ode/>
              </torsional>
              <ode/>
            </friction>
          </surface>
        </collision>
        <visual name='shoulder_link_visual'>
          <pose>0 0 0 0 -0 3.14159</pose>
          <geometry>
            <mesh>
              <scale>1 1 1</scale>
              <uri>file:///root/ros2_ws/install/ur_description/share/ur_description/meshes/ur10e/visual/shoulder.dae</uri>
            </mesh>
          </geometry>
        </visual>
        <self_collide>0</self_collide>
        <enable_wind>0</enable_wind>
        <kinematic>0</kinematic>
      </link>
      <joint name='shoulder_lift_joint' type='revolute'>
        <pose relative_to='shoulder_link'>0 0 0 1.5708 -0 0</pose>
        <parent>shoulder_link</parent>
        <child>upper_arm_link</child>
        <axis>
          <xyz>0 0 1</xyz>
          <limit>
            <lower>-6.28319</lower>
            <upper>6.28319</upper>
            <effort>330</effort>
            <velocity>2.0944</velocity>
          </limit>
          <dynamics>
            <damping>0</damping>
            <friction>0</friction>
            <spring_reference>0</spring_reference>
            <spring_stiffness>0</spring_stiffness>
          </dynamics>
        </axis>
      </joint>
      <link name='upper_arm_link'>
        <pose relative_to='shoulder_lift_joint'>0 0 0 0 -0 0</pose>
        <inertial>
          <pose>-0.1764 0 0.16 0 -0 0</pose>
          <mass>10.45</mass>
          <inertia>
            <ixx>0.02796</ixx>
            <ixy>-0.0001</ixy>
            <ixz>-0.0072</ixz>
            <iyy>0.47558</iyy>
            <iyz>3e-05</iyz>
            <izz>0.47635</izz>
          </inertia>
        </inertial>
        <collision name='upper_arm_link_collision'>
          <pose>0 0 0.176 1.5708 0 -1.5708</pose>
          <geometry>
            <mesh>
              <scale>1 1 1</scale>
              <uri>file:///root/ros2_ws/install/ur_description/share/ur_description/meshes/ur16e/collision/upperarm.stl</uri>
            </mesh>
          </geometry>
          <max_contacts>10</max_contacts>
          <surface>
            <contact>
              <ode/>
            </contact>
            <bounce/>
            <friction>
              <torsional>
                <ode/>
              </torsional>
              <ode/>
            </friction>
          </surface>
        </collision>
        <visual name='upper_arm_link_visual'>
          <pose>0 0 0.176 1.5708 0 -1.5708</pose>
          <geometry>
            <mesh>
              <scale>1 1 1</scale>
              <uri>file:///root/ros2_ws/install/ur_description/share/ur_description/meshes/ur16e/visual/upperarm.dae</uri>
            </mesh>
          </geometry>
        </visual>
        <self_collide>0</self_collide>
        <enable_wind>0</enable_wind>
        <kinematic>0</kinematic>
      </link>
      <joint name='elbow_joint' type='revolute'>
        <pose relative_to='upper_arm_link'>-0.4784 0 0 0 -0 0</pose>
        <parent>upper_arm_link</parent>
        <child>forearm_link</child>
        <axis>
          <xyz>0 0 1</xyz>
          <limit>
            <lower>-3.14159</lower>
            <upper>3.14159</upper>
            <effort>150</effort>
            <velocity>3.14159</velocity>
          </limit>
          <dynamics>
            <damping>0</damping>
            <friction>0</friction>
            <spring_reference>0</spring_reference>
            <spring_stiffness>0</spring_stiffness>
          </dynamics>
        </axis>
      </joint>
      <link name='forearm_link'>
        <pose relative_to='elbow_joint'>0 0 0 0 -0 0</pose>
        <inertial>
          <pose>-0.166 0 0.065 0 -0 0</pose>
          <mass>4.321</mass>
          <inertia>
            <ixx>0.01091</ixx>
            <ixy>6e-05</ixy>
            <ixz>0.01012</ixz>
            <iyy>0.1206</iyy>
            <iyz>1e-05</iyz>
            <izz>0.11714</izz>
          </inertia>
        </inertial>
        <collision name='forearm_link_collision'>
          <pose>0 0 0.04 1.5708 0 -1.5708</pose>
          <geometry>
            <mesh>
              <scale>1 1 1</scale>
              <uri>file:///root/ros2_ws/install/ur_description/share/ur_description/meshes/ur16e/collision/forearm.stl</uri>
            </mesh>
          </geometry>
          <max_contacts>10</max_contacts>
          <surface>
            <contact>
              <ode/>
            </contact>
            <bounce/>
            <friction>
              <torsional>
                <ode/>
              </torsional>
              <ode/>
            </friction>
          </surface>
        </collision>
        <visual name='forearm_link_visual'>
          <pose>0 0 0.04 1.5708 0 -1.5708</pose>
          <geometry>
            <mesh>
              <scale>1 1 1</scale>
              <uri>file:///root/ros2_ws/install/ur_description/share/ur_description/meshes/ur16e/visual/forearm.dae</uri>
            </mesh>
          </geometry>
        </visual>
        <self_collide>0</self_collide>
        <enable_wind>0</enable_wind>
        <kinematic>0</kinematic>
      </link>
      <joint name='wrist_1_joint' type='revolute'>
        <pose relative_to='forearm_link'>-0.36 0 0.17415 0 -0 0</pose>
        <parent>forearm_link</parent>
        <child>wrist_1_link</child>
        <axis>
          <xyz>0 0 1</xyz>
          <limit>
            <lower>-6.28319</lower>
            <upper>6.28319</upper>
            <effort>54</effort>
            <velocity>3.14159</velocity>
          </limit>
          <dynamics>
            <damping>0</damping>
            <friction>0</friction>
            <spring_reference>0</spring_reference>
            <spring_stiffness>0</spring_stiffness>
          </dynamics>
        </axis>
      </joint>
      <link name='wrist_1_link'>
        <pose relative_to='wrist_1_joint'>0 0 0 0 -0 0</pose>
        <inertial>
          <pose>0 -0.011 -0.009 1.5708 -0 0</pose>
          <mass>2.18</mass>
          <inertia>
            <ixx>0.00609</ixx>
            <ixy>-1e-05</ixy>
            <ixz>0</ixz>
            <iyy>0.00245</iyy>
            <iyz>0.00083</iyz>
            <izz>0.00579</izz>
          </inertia>
        </inertial>
        <collision name='wrist_1_link_collision'>
          <pose>0 0 -0.135 1.5708 -0 0</pose>
          <geometry>
            <mesh>
              <scale>1 1 1</scale>
              <uri>file:///root/ros2_ws/install/ur_description/share/ur_description/meshes/ur10e/collision/wrist1.stl</uri>
            </mesh>
          </geometry>
          <max_contacts>10</max_contacts>
          <surface>
            <contact>
              <ode/>
            </contact>
            <bounce/>
            <friction>
              <torsional>
                <ode/>
              </torsional>
              <ode/>
            </friction>
          </surface>
        </collision>
        <visual name='wrist_1_link_visual'>
          <pose>0 0 -0.135 1.5708 -0 0</pose>
          <geometry>
            <mesh>
              <scale>1 1 1</scale>
              <uri>file:///root/ros2_ws/install/ur_description/share/ur_description/meshes/ur10e/visual/wrist1.dae</uri>
            </mesh>
          </geometry>
        </visual>
        <self_collide>0</self_collide>
        <enable_wind>0</enable_wind>
        <kinematic>0</kinematic>
      </link>
      <joint name='wrist_2_joint' type='revolute'>
        <pose relative_to='wrist_1_link'>0 -0.11985 -0 1.5708 -0 0</pose>
        <parent>wrist_1_link</parent>
        <child>wrist_2_link</child>
        <axis>
          <xyz>0 0 1</xyz>
          <limit>
            <lower>-6.28319</lower>
            <upper>6.28319</upper>
            <effort>54</effort>
            <velocity>3.14159</velocity>
          </limit>
          <dynamics>
            <damping>0</damping>
            <friction>0</friction>
            <spring_reference>0</spring_reference>
            <spring_stiffness>0</spring_stiffness>
          </dynamics>
        </axis>
      </joint>
      <link name='wrist_2_link'>
        <pose relative_to='wrist_2_joint'>0 0 0 0 -0 0</pose>
        <inertial>
          <pose>0 0.012 -0.018 -1.5708 0 0</pose>
          <mass>2.033</mass>
          <inertia>
            <ixx>0.00389</ixx>
            <ixy>-1e-05</ixy>
            <ixz>0</ixz>
            <iyy>0.00219</iyy>
            <iyz>-0.00045</iyz>
            <izz>0.00363</izz>
          </inertia>
        </inertial>
        <collision name='wrist_2_link_collision'>
          <pose>0 0 -0.12 0 -0 0</pose>
          <geometry>
            <mesh>
              <scale>1 1 1</scale>
              <uri>file:///root/ros2_ws/install/ur_description/share/ur_description/meshes/ur10e/collision/wrist2.stl</uri>
            </mesh>
          </geometry>
          <max_contacts>10</max_contacts>
          <surface>
            <contact>
              <ode/>
            </contact>
            <bounce/>
            <friction>
              <torsional>
                <ode/>
              </torsional>
              <ode/>
            </friction>
          </surface>
        </collision>
        <visual name='wrist_2_link_visual'>
          <pose>0 0 -0.12 0 -0 0</pose>
          <geometry>
            <mesh>
              <scale>1 1 1</scale>
              <uri>file:///root/ros2_ws/install/ur_description/share/ur_description/meshes/ur10e/visual/wrist2.dae</uri>
            </mesh>
          </geometry>
        </visual>
        <self_collide>0</self_collide>
        <enable_wind>0</enable_wind>
        <kinematic>0</kinematic>
      </link>
      <joint name='wrist_3_joint' type='revolute'>
        <pose relative_to='wrist_2_link'>0 0.11655 -0 -1.5708 0 0</pose>
        <parent>wrist_2_link</parent>
        <child>wrist_3_link</child>
        <axis>
          <xyz>0 0 1</xyz>
          <limit>
            <lower>-6.28319</lower>
            <upper>6.28319</upper>
            <effort>54</effort>
            <velocity>3.14159</velocity>
          </limit>
          <dynamics>
            <damping>0</damping>
            <friction>0</friction>
            <spring_reference>0</spring_reference>
            <spring_stiffness>0</spring_stiffness>
          </dynamics>
        </axis>
      </joint>
      <link name='wrist_3_link'>
        <pose relative_to='wrist_3_joint'>0 0 0 0 -0 0</pose>
        <inertial>
          <pose>0 0 -0.044 0 -0 0</pose>
          <mass>0.907</mass>
          <inertia>
            <ixx>0.00117</ixx>
            <ixy>0</ixy>
            <ixz>0</ixz>
            <iyy>0.00118</iyy>
            <iyz>0</iyz>
            <izz>0.00084</izz>
          </inertia>
        </inertial>
        <collision name='wrist_3_link_collision'>
          <pose>0 0 -0.1168 1.5708 -0 0</pose>
          <geometry>
            <mesh>
              <scale>1 1 1</scale>
              <uri>file:///root/ros2_ws/install/ur_description/share/ur_description/meshes/ur10e/collision/wrist3.stl</uri>
            </mesh>
          </geometry>
          <max_contacts>10</max_contacts>
          <surface>
            <contact>
              <ode/>
            </contact>
            <bounce/>
            <friction>
              <torsional>
                <ode/>
              </torsional>
              <ode/>
            </friction>
          </surface>
        </collision>
        <visual name='wrist_3_link_visual'>
          <pose>0 0 -0.1168 1.5708 -0 0</pose>
          <geometry>
            <mesh>
              <scale>1 1 1</scale>
              <uri>file:///root/ros2_ws/install/ur_description/share/ur_description/meshes/ur10e/visual/wrist3.dae</uri>
            </mesh>
          </geometry>
        </visual>
        <self_collide>0</self_collide>
        <enable_wind>0</enable_wind>
        <kinematic>0</kinematic>
      </link>
      <static>0</static>
      <plugin name='gazebo_ros2_control' filename='libgazebo_ros2_control.so'>
        <parameters>/root/ros2_ws/install/ur_yt_sim/share/ur_yt_sim/config/ur16e_controllers.yaml</parameters>
      </plugin>
      <pose>0 0 0 0 -0 0</pose>
    </model>
    <state world_name='default'>
      <sim_time>220 519000000</sim_time>
      <real_time>134 909447552</real_time>
      <wall_time>1760631779 121684595</wall_time>
      <iterations>122214</iterations>
      <model name='box_base'>
        <pose>395.064 -657.168 0.102393 0 -0 -2.1e-05</pose>
        <scale>1 1 1</scale>
        <link name='link_1'>
          <pose>0.000548 0.00014 0.174992 0 -0 -2.1e-05</pose>
          <velocity>0 0 0 0 -0 0</velocity>
          <acceleration>0 0 -9.8 -0 -0 -0</acceleration>
          <wrench>0 0 -9.8 0 -0 0</wrench>
        </link>
        <model name='prius_hybrid'>
          <pose>790.137 -1314.33 0.029894 0 0 -1.3e-05</pose>
          <scale>1 1 1</scale>
          <link name='chassis'>
            <pose>790.138 -1314.33 0.011641 -2e-06 -0 0.000613</pose>
            <velocity>9e-06 1.6e-05 2.1e-05 -3e-06 -0 5e-06</velocity>
            <acceleration>0 -0 0 0 -0 0</acceleration>
            <wrench>0 -1.5e-05 0 0 -0 0</wrench>
          </link>
          <link name='front_left_wheel'>
            <pose>790.899 -1315.74 0.311646 -0.00825 0.006367 0.07345</pose>
            <velocity>1.6e-05 2.2e-05 3.2e-05 -6.8e-05 5e-05 0.00064</velocity>
            <acceleration>0 -0 -0 0 -0 1e-06</acceleration>
            <wrench>0 -0 -0 0 -0 0</wrench>
          </link>
          <link name='front_right_wheel'>
            <pose>789.379 -1315.74 0.311646 -0.005278 0.006165 0.071126</pose>
            <velocity>1.6e-05 1.4e-05 3.1e-05 -4.3e-05 5e-05 0.000609</velocity>
            <acceleration>0 -0 0 0 -0 0</acceleration>
            <wrench>0 -0 0 0 -0 0</wrench>
          </link>
          <link name='rear_axle'>
            <pose>790.137 -1312.88 0.311637 -2e-06 -4e-06 0.000613</pose>
            <velocity>1e-06 1.7e-05 1.5e-05 -4e-06 -4e-06 5e-06</velocity>
            <acceleration>-0 -0 -0 -0.000711 -0 -0</acceleration>
            <wrench>-0 -0 -0 0 -0 0</wrench>
          </link>
          <link name='rear_left_wheel'>
            <pose>790.923 -1312.88 0.311647 -0.008678 -3e-06 0.000613</pose>
            <velocity>1e-06 2.1e-05 2.5e-05 -6.8e-05 -1e-06 5e-06</velocity>
            <acceleration>0 -0 0 0 -0 0</acceleration>
            <wrench>0 -0 0 0 -0 0</wrench>
          </link>
          <link name='rear_right_wheel'>
            <pose>789.351 -1312.88 0.311647 -0.005555 8e-06 0.000613</pose>
            <velocity>2e-06 1.3e-05 2.5e-05 -4.3e-05 2e-06 5e-06</velocity>
            <acceleration>-0 -0 0 0 -0 0</acceleration>
            <wrench>-0 -0 0 0 -0 0</wrench>
          </link>
          <link name='steering_wheel'>
            <pose>790.495 -1314.95 0.997994 -0.619559 1.23856 0.925118</pose>
            <velocity>5e-06 2.2e-05 2.1e-05 -5e-06 0.003587 0.000993</velocity>
            <acceleration>0 -0 0 -3e-06 0.004657 0.000156</acceleration>
            <wrench>0 -0 0 0 -0 0</wrench>
          </link>
        </model>
      </model>
      <model name='car_with_inlet_v3'>
        <pose>-0.502967 1.20468 0.411376 0.000403 -0.000104 -1.50585</pose>
        <scale>1 1 1</scale>
        <model name='inlet'>
          <pose>0.259184 0.818228 0.79989 -8.4e-05 -0.000408 0.014171</pose>
          <scale>1 1 1</scale>
          <link name='link'>
            <pose>0.259184 0.818228 0.79989 -8.4e-05 -0.000408 0.014171</pose>
            <velocity>2e-05 0 0 -1e-06 -0 3e-06</velocity>
            <acceleration>0.020398 0.000286 0.000227 -0.000845 -0.000371 0.003235</acceleration>
            <wrench>0.008159 0.000114 9.1e-05 0 -0 0</wrench>
          </link>
        </model>
        <model name='prius_hybrid'>
          <pose>-1.29237 1.63533 0.000962 0.000276 0.004322 -1.50715</pose>
          <scale>1 1 1</scale>
          <link name='chassis'>
            <pose>-1.29017 1.63512 0.011641 -2e-06 -0 -1.50585</pose>
            <velocity>1.6e-05 -5e-06 2.1e-05 0 3e-06 3e-06</velocity>
            <acceleration>-0 -0 0 0.000546 2.7e-05 0</acceleration>
            <wrench>-1.1e-05 -0 0 0 -0 0</wrench>
          </link>
          <link name='front_left_wheel'>
            <pose>-2.64787 0.785208 0.311646 -0.008352 0.009235 -1.4001</pose>
            <velocity>2.1e-05 -9e-06 3.2e-05 2.8e-05 6.4e-05 0.000452</velocity>
            <acceleration>-0 -0 -0 0 -0 0</acceleration>
            <wrench>-0 -0 -0 0 -0 0</wrench>
          </link>
          <link name='front_right_wheel'>
            <pose>-2.74653 2.302 0.311646 -0.003389 0.004596 -1.4533</pose>
            <velocity>1.6e-05 -9e-06 3.1e-05 2.9e-05 4.9e-05 0.000393</velocity>
            <acceleration>-0 -0 0 0 -0 0</acceleration>
            <wrench>-0 -0 0 0 -0 0</wrench>
          </link>
          <link name='rear_axle'>
            <pose>0.15677 1.72922 0.311637 -2e-06 -5e-06 -1.50585</pose>
            <velocity>1.7e-05 -0 1.5e-05 -4e-06 4e-06 3e-06</velocity>
            <acceleration>-0 -0 0 0.025903 -0.073873 -0</acceleration>
            <wrench>-0 -0 0 0 -0 0</wrench>
          </link>
          <link name='rear_left_wheel'>
            <pose>0.207783 0.944882 0.311647 -0.00773 -3e-06 -1.50585</pose>
            <velocity>2e-05 0 2.5e-05 -5e-06 6.2e-05 3e-06</velocity>
            <acceleration>-0 -0 0 0 -0 0</acceleration>
            <wrench>-0 -0 0 0 -0 0</wrench>
          </link>
          <link name='rear_right_wheel'>
            <pose>0.105757 2.51357 0.311647 -0.004238 9e-06 -1.50585</pose>
            <velocity>1.5e-05 -1e-06 2.5e-05 -1e-06 4.8e-05 3e-06</velocity>
            <acceleration>-0 -0 0 0 -0 0</acceleration>
            <wrench>-0 -0 0 0 -0 0</wrench>
          </link>
          <link name='steering_wheel'>
            <pose>-1.89308 1.23903 0.997994 -0.617774 1.239 -0.579456</pose>
            <velocity>2.1e-05 1e-06 2.1e-05 0.003565 0.000235 0.000987</velocity>
            <acceleration>-0 -0 0 0.004629 0.000301 0.000155</acceleration>
            <wrench>-0 -0 0 0 -0 0</wrench>
          </link>
        </model>
      </model>
      <model name='ground_plane'>
        <pose>0 0 0 0 -0 0</pose>
        <scale>1 1 1</scale>
        <link name='link'>
          <pose>0 0 0 0 -0 0</pose>
          <velocity>0 0 0 0 -0 0</velocity>
          <acceleration>0 0 0 0 -0 0</acceleration>
          <wrench>0 0 0 0 -0 0</wrench>
        </link>
      </model>
      <model name='ur'>
        <pose>0 1.8e-05 0 5.1e-05 -0 0</pose>
        <scale>1 1 1</scale>
        <link name='base_link'>
          <pose>-0 -0 0.35 5.1e-05 -0 0</pose>
          <velocity>0 0 0 -0 -0 -0</velocity>
          <acceleration>0 0 0 0 -0 0</acceleration>
          <wrench>0 0 0 0 -0 0</wrench>
        </link>
        <link name='forearm_link'>
          <pose>0.000385 6.1e-05 1.0091 1.75063 1.56999 -2.96189</pose>
          <velocity>1.6e-05 0 -0 0 -1.7e-05 6e-05</velocity>
          <acceleration>0.009294 3e-05 -1.1e-05 0.005185 0.041054 0.681048</acceleration>
          <wrench>0.040157 0.000129 -4.6e-05 0 -0 0</wrench>
        </link>
        <link name='shoulder_link'>
          <pose>0 -9e-06 0.530699 0.000111 -0 3.14147</pose>
          <velocity>0 0 0 0 -0 6e-05</velocity>
          <acceleration>-0.001797 0 0 7.8e-05 -0.02176 0.062307</acceleration>
          <wrench>-0.013241 2e-06 0 0 -0 0</wrench>
        </link>
        <link name='upper_arm_link'>
          <pose>0 -9e-06 0.530698 1.74805 1.56998 -2.96446</pose>
          <velocity>-0 0 -0 0 3.4e-05 6e-05</velocity>
          <acceleration>-0.003657 9e-06 -5e-06 6.8e-05 0.018336 1.01572</acceleration>
          <wrench>-0.038216 9.4e-05 -5e-05 0 -0 0</wrench>
        </link>
        <link name='wrist_1_link'>
          <pose>0.000693 0.174264 1.36907 -1.57094 0.001605 -0.000126</pose>
          <velocity>-1e-06 0 -0 0 0.000131 6e-05</velocity>
          <acceleration>0.001362 4.1e-05 -1e-05 0.000367 0.301035 -0.036585</acceleration>
          <wrench>0.00297 9e-05 -2.2e-05 0 -0 0</wrench>
        </link>
        <link name='wrist_2_link'>
          <pose>0.000886 0.174282 1.48892 -0.000151 0.001605 -0.000134</pose>
          <velocity>1.5e-05 0 -0 0 0.000131 -2.1e-05</velocity>
          <acceleration>0.012951 4.8e-05 -3.1e-05 -0.000151 0.130708 -0.021041</acceleration>
          <wrench>0.02633 9.8e-05 -6.3e-05 0 -0 0</wrench>
        </link>
        <link name='wrist_3_link'>
          <pose>0.000901 0.290832 1.4889 -1.57096 0.001587 -0.000134</pose>
          <velocity>1.8e-05 0 -0 -0 -0 -2.1e-05</velocity>
          <acceleration>0.016578 5e-05 -4.3e-05 -0.000131 -4e-06 -0.014973</acceleration>
          <wrench>0.015036 4.5e-05 -3.9e-05 0 -0 0</wrench>
        </link>
      </model>
      <light name='sun'>
        <pose>0 0 10 0 -0 0</pose>
      </light>
    </state>
    <gui fullscreen='0'>
      <camera name='user_camera'>
        <pose>2.62205 -0.188538 1.23916 0 0.34171 2.50764</pose>
        <view_controller>ortho</view_controller>
        <projection_type>orthographic</projection_type>
      </camera>
    </gui>
    <model name='box_base'>
      <link name='link_1'>
        <inertial>
          <mass>1</mass>
          <inertia>
            <ixx>0.166667</ixx>
            <ixy>0</ixy>
            <ixz>0</ixz>
            <iyy>0.166667</iyy>
            <iyz>0</iyz>
            <izz>0.166667</izz>
          </inertia>
          <pose>0 0 0 0 -0 0</pose>
        </inertial>
        <pose>-395.077 657.16 0.0725 0 -0 0</pose>
        <gravity>1</gravity>
        <self_collide>0</self_collide>
        <kinematic>0</kinematic>
        <enable_wind>0</enable_wind>
        <visual name='visual'>
          <pose>0 0 0 0 -0 0</pose>
          <geometry>
            <box>
              <size>0.5 0.5 0.35</size>
            </box>
          </geometry>
          <material>
            <lighting>1</lighting>
            <script>
              <uri>file://media/materials/scripts/gazebo.material</uri>
              <name>Gazebo/Grey</name>
            </script>
            <shader type='pixel'>
              <normal_map>__default__</normal_map>
            </shader>
            <ambient>0 0 0.3 1</ambient>
            <diffuse>0.7 0.7 0.7 1</diffuse>
            <specular>0.01 0.01 0.01 1</specular>
            <emissive>0 0 0 1</emissive>
          </material>
          <transparency>0</transparency>
          <cast_shadows>1</cast_shadows>
        </visual>
        <collision name='collision'>
          <laser_retro>0</laser_retro>
          <max_contacts>10</max_contacts>
          <pose>0 0 0 0 -0 0</pose>
          <geometry>
            <box>
              <size>0.5 0.5 0.35</size>
            </box>
          </geometry>
          <surface>
            <friction>
              <ode>
                <mu>1</mu>
                <mu2>1</mu2>
                <fdir1>0 0 0</fdir1>
                <slip1>0</slip1>
                <slip2>0</slip2>
              </ode>
              <torsional>
                <coefficient>1</coefficient>
                <patch_radius>0</patch_radius>
                <surface_radius>0</surface_radius>
                <use_patch_radius>1</use_patch_radius>
                <ode>
                  <slip>0</slip>
                </ode>
              </torsional>
            </friction>
            <bounce>
              <restitution_coefficient>0</restitution_coefficient>
              <threshold>1e+06</threshold>
            </bounce>
            <contact>
              <collide_without_contact>0</collide_without_contact>
              <collide_without_contact_bitmask>1</collide_without_contact_bitmask>
              <collide_bitmask>1</collide_bitmask>
              <ode>
                <soft_cfm>0</soft_cfm>
                <soft_erp>0.2</soft_erp>
                <kp>1e+13</kp>
                <kd>1</kd>
                <max_vel>0.01</max_vel>
                <min_depth>0</min_depth>
              </ode>
              <bullet>
                <split_impulse>1</split_impulse>
                <split_impulse_penetration_threshold>-0.01</split_impulse_penetration_threshold>
                <soft_cfm>0</soft_cfm>
                <soft_erp>0.2</soft_erp>
                <kp>1e+13</kp>
                <kd>1</kd>
              </bullet>
            </contact>
          </surface>
        </collision>
      </link>
      <model name='prius_hybrid'>
        <pose>395.077 -657.164 -0.0725 0 -0 0</pose>
        <link name='chassis'>
          <inertial>
            <mass>1326</mass>
            <pose>0 -0.266 0.48 0 -0 0</pose>
            <inertia>
              <ixx>2581.13</ixx>
              <ixy>0</ixy>
              <iyy>591.308</iyy>
              <ixz>0</ixz>
              <iyz>0</iyz>
              <izz>2681.95</izz>
            </inertia>
          </inertial>
          <visual name='chassis_visual'>
            <geometry>
              <mesh>
                <uri>model://prius_hybrid/meshes/Hybrid.obj</uri>
                <scale>0.01 0.01 0.01</scale>
                <submesh>
                  <name>Hybrid</name>
                  <center>0</center>
                </submesh>
              </mesh>
            </geometry>
          </visual>
          <visual name='interior_visual'>
            <geometry>
              <mesh>
                <uri>model://prius_hybrid/meshes/Hybrid.obj</uri>
                <scale>0.01 0.01 0.01</scale>
                <submesh>
                  <name>Hybrid_Interior</name>
                  <center>0</center>
                </submesh>
              </mesh>
            </geometry>
          </visual>
          <visual name='windows_visual'>
            <geometry>
              <mesh>
                <uri>model://prius_hybrid/meshes/Hybrid.obj</uri>
                <scale>0.01 0.01 0.01</scale>
                <submesh>
                  <name>Hybrid_Windows</name>
                  <center>0</center>
                </submesh>
              </mesh>
            </geometry>
          </visual>
          <collision name='chassis'>
            <pose>0 0.05 0.625 0 -0 0</pose>
            <geometry>
              <box>
                <size>1.7526 2.1 0.95</size>
              </box>
            </geometry>
            <max_contacts>10</max_contacts>
            <surface>
              <contact>
                <ode/>
              </contact>
              <bounce/>
              <friction>
                <torsional>
                  <ode/>
                </torsional>
                <ode/>
              </friction>
            </surface>
          </collision>
          <collision name='front_bumper'>
            <pose>0 -2 0.458488 0 -0 0</pose>
            <geometry>
              <box>
                <size>1.33728 0.48 0.566691</size>
              </box>
            </geometry>
            <max_contacts>10</max_contacts>
            <surface>
              <contact>
                <ode/>
              </contact>
              <bounce/>
              <friction>
                <torsional>
                  <ode/>
                </torsional>
                <ode/>
              </friction>
            </surface>
          </collision>
          <collision name='hood'>
            <pose>0 -1.90084 0.676305 0.341247 -0 0</pose>
            <geometry>
              <box>
                <size>1.59797 0.493107 0.265468</size>
              </box>
            </geometry>
            <max_contacts>10</max_contacts>
            <surface>
              <contact>
                <ode/>
              </contact>
              <bounce/>
              <friction>
                <torsional>
                  <ode/>
                </torsional>
                <ode/>
              </friction>
            </surface>
          </collision>
          <collision name='windshield'>
            <pose>0 -0.875105 1.03227 0.335476 -0 0</pose>
            <geometry>
              <box>
                <size>1.16838 1.65425 0.272347</size>
              </box>
            </geometry>
            <max_contacts>10</max_contacts>
            <surface>
              <contact>
                <ode/>
              </contact>
              <bounce/>
              <friction>
                <torsional>
                  <ode/>
                </torsional>
                <ode/>
              </friction>
            </surface>
          </collision>
          <collision name='top_front'>
            <pose>0 0.161236 1.38604 0.13503 -0 0</pose>
            <geometry>
              <box>
                <size>1.27915 0.625988 0.171868</size>
              </box>
            </geometry>
            <max_contacts>10</max_contacts>
            <surface>
              <contact>
                <ode/>
              </contact>
              <bounce/>
              <friction>
                <torsional>
                  <ode/>
                </torsional>
                <ode/>
              </friction>
            </surface>
          </collision>
          <collision name='top_rear'>
            <pose>0 0.817696 1.36007 -0.068997 0 0</pose>
            <geometry>
              <box>
                <size>1.28513 0.771189 0.226557</size>
              </box>
            </geometry>
            <max_contacts>10</max_contacts>
            <surface>
              <contact>
                <ode/>
              </contact>
              <bounce/>
              <friction>
                <torsional>
                  <ode/>
                </torsional>
                <ode/>
              </friction>
            </surface>
          </collision>
          <collision name='rear_window'>
            <pose>0 1.64053 1.17513 -0.262017 0 0</pose>
            <geometry>
              <box>
                <size>1.26785 1.11634 0.244286</size>
              </box>
            </geometry>
            <max_contacts>10</max_contacts>
            <surface>
              <contact>
                <ode/>
              </contact>
              <bounce/>
              <friction>
                <torsional>
                  <ode/>
                </torsional>
                <ode/>
              </friction>
            </surface>
          </collision>
          <collision name='trunk'>
            <pose>0 1.63706 0.88818 0 -0 0</pose>
            <geometry>
              <box>
                <size>1.78806 1.13899 0.482746</size>
              </box>
            </geometry>
            <max_contacts>10</max_contacts>
            <surface>
              <contact>
                <ode/>
              </contact>
              <bounce/>
              <friction>
                <torsional>
                  <ode/>
                </torsional>
                <ode/>
              </friction>
            </surface>
          </collision>
          <collision name='back_bumper'>
            <pose>0 2.05445 0.57787 0 -0 0</pose>
            <geometry>
              <box>
                <size>1.78165 0.512093 0.581427</size>
              </box>
            </geometry>
            <max_contacts>10</max_contacts>
            <surface>
              <contact>
                <ode/>
              </contact>
              <bounce/>
              <friction>
                <torsional>
                  <ode/>
                </torsional>
                <ode/>
              </friction>
            </surface>
          </collision>
          <self_collide>0</self_collide>
          <enable_wind>0</enable_wind>
          <kinematic>0</kinematic>
        </link>
        <link name='steering_wheel'>
          <pose>0.357734 -0.627868 0.988243 -1.3021 0 0</pose>
          <inertial>
            <mass>1</mass>
            <inertia>
              <ixx>0.145833</ixx>
              <ixy>0</ixy>
              <ixz>0</ixz>
              <iyy>0.145833</iyy>
              <iyz>0</iyz>
              <izz>0.125</izz>
            </inertia>
            <pose>0 0 0 0 -0 0</pose>
          </inertial>
          <collision name='collision'>
            <geometry>
              <cylinder>
                <radius>0.178172</radius>
                <length>0.041845</length>
              </cylinder>
            </geometry>
            <surface>
              <contact>
                <ode>
                  <min_depth>0.003</min_depth>
                </ode>
              </contact>
              <bounce/>
              <friction>
                <torsional>
                  <ode/>
                </torsional>
                <ode/>
              </friction>
            </surface>
            <max_contacts>10</max_contacts>
          </collision>
          <visual name='visual'>
            <pose>0 0 0 1.3021 -0 0</pose>
            <geometry>
              <mesh>
                <uri>model://prius_hybrid/meshes/Hybrid.obj</uri>
                <scale>0.01 0.01 0.01</scale>
                <submesh>
                  <name>Steering_Wheel</name>
                  <center>1</center>
                </submesh>
              </mesh>
            </geometry>
          </visual>
          <self_collide>0</self_collide>
          <enable_wind>0</enable_wind>
          <kinematic>0</kinematic>
        </link>
        <link name='front_left_wheel'>
          <pose>0.76 -1.41 0.3 0 -0 0</pose>
          <inertial>
            <mass>11</mass>
            <inertia>
              <ixx>0.586312</ixx>
              <ixy>0</ixy>
              <iyy>0.335529</iyy>
              <ixz>0</ixz>
              <iyz>0</iyz>
              <izz>0.335529</izz>
            </inertia>
            <pose>0 0 0 0 -0 0</pose>
          </inertial>
          <visual name='visual'>
            <pose>0.04 0 0 0 -0 0</pose>
            <geometry>
              <mesh>
                <uri>model://prius_hybrid/meshes/Hybrid.obj</uri>
                <scale>0.01 0.01 0.01</scale>
                <submesh>
                  <name>Wheel_Front_Left_</name>
                  <center>1</center>
                </submesh>
              </mesh>
            </geometry>
          </visual>
          <collision name='collision'>
            <pose>0 0 0 3.14159 1.57079 3.14159</pose>
            <geometry>
              <sphere>
                <radius>0.31265</radius>
              </sphere>
            </geometry>
            <surface>
              <friction>
                <ode>
                  <mu>0.9</mu>
                  <mu2>0.9</mu2>
                  <slip1>0</slip1>
                  <slip2>0</slip2>
                </ode>
                <torsional>
                  <ode/>
                </torsional>
              </friction>
              <contact>
                <ode>
                  <min_depth>0.001</min_depth>
                  <kp>1e+09</kp>
                </ode>
              </contact>
              <bounce/>
            </surface>
            <max_contacts>10</max_contacts>
          </collision>
          <self_collide>0</self_collide>
          <enable_wind>0</enable_wind>
          <kinematic>0</kinematic>
        </link>
        <link name='front_right_wheel'>
          <pose>-0.76 -1.41 0.3 0 -0 0</pose>
          <inertial>
            <mass>11</mass>
            <inertia>
              <ixx>0.586312</ixx>
              <ixy>0</ixy>
              <iyy>0.335529</iyy>
              <ixz>0</ixz>
              <iyz>0</iyz>
              <izz>0.335529</izz>
            </inertia>
            <pose>0 0 0 0 -0 0</pose>
          </inertial>
          <visual name='visual'>
            <pose>-0.04 0 0 0 -0 0</pose>
            <pose>0 0 0 0 -0 0</pose>
            <geometry>
              <mesh>
                <uri>model://prius_hybrid/meshes/Hybrid.obj</uri>
                <scale>0.01 0.01 0.01</scale>
                <submesh>
                  <name>Wheel_Front_Right</name>
                  <center>1</center>
                </submesh>
              </mesh>
            </geometry>
          </visual>
          <collision name='collision'>
            <pose>0 0 0 3.14159 1.57079 3.14159</pose>
            <geometry>
              <sphere>
                <radius>0.31265</radius>
              </sphere>
            </geometry>
            <surface>
              <friction>
                <ode>
                  <mu>0.9</mu>
                  <mu2>0.9</mu2>
                  <slip1>0</slip1>
                  <slip2>0</slip2>
                </ode>
                <torsional>
                  <ode/>
                </torsional>
              </friction>
              <contact>
                <ode>
                  <min_depth>0.001</min_depth>
                  <kp>1e+09</kp>
                </ode>
              </contact>
              <bounce/>
            </surface>
            <max_contacts>10</max_contacts>
          </collision>
          <self_collide>0</self_collide>
          <enable_wind>0</enable_wind>
          <kinematic>0</kinematic>
        </link>
        <link name='rear_left_wheel'>
          <pose>0.786 1.45 0.3 0 -0 0</pose>
          <inertial>
            <mass>11</mass>
            <inertia>
              <ixx>0.586312</ixx>
              <ixy>0</ixy>
              <iyy>0.335529</iyy>
              <ixz>0</ixz>
              <iyz>0</iyz>
              <izz>0.335529</izz>
            </inertia>
            <pose>0 0 0 0 -0 0</pose>
          </inertial>
          <visual name='visual'>
            <pose>0.04 0 0 0 -0 0</pose>
            <geometry>
              <mesh>
                <uri>model://prius_hybrid/meshes/Hybrid.obj</uri>
                <scale>0.01 0.01 0.01</scale>
                <submesh>
                  <name>Wheel_Front_Left_</name>
                  <center>1</center>
                </submesh>
              </mesh>
            </geometry>
          </visual>
          <collision name='collision'>
            <pose>0 0 0 3.14159 1.57079 3.14159</pose>
            <geometry>
              <sphere>
                <radius>0.31265</radius>
              </sphere>
            </geometry>
            <surface>
              <friction>
                <ode>
                  <mu>1.1</mu>
                  <mu2>1.1</mu2>
                  <slip1>0</slip1>
                  <slip2>0</slip2>
                </ode>
                <torsional>
                  <ode/>
                </torsional>
              </friction>
              <contact>
                <ode>
                  <min_depth>0.001</min_depth>
                  <kp>1e+09</kp>
                </ode>
              </contact>
              <bounce/>
            </surface>
            <max_contacts>10</max_contacts>
          </collision>
          <self_collide>0</self_collide>
          <enable_wind>0</enable_wind>
          <kinematic>0</kinematic>
        </link>
        <link name='rear_right_wheel'>
          <pose>-0.786 1.45 0.3 0 -0 0</pose>
          <inertial>
            <mass>11</mass>
            <inertia>
              <ixx>0.586312</ixx>
              <ixy>0</ixy>
              <iyy>0.335529</iyy>
              <ixz>0</ixz>
              <iyz>0</iyz>
              <izz>0.335529</izz>
            </inertia>
            <pose>0 0 0 0 -0 0</pose>
          </inertial>
          <visual name='visual'>
            <pose>-0.04 0 0 0 -0 0</pose>
            <geometry>
              <mesh>
                <uri>model://prius_hybrid/meshes/Hybrid.obj</uri>
                <scale>0.01 0.01 0.01</scale>
                <submesh>
                  <name>Wheel_Front_Right</name>
                  <center>1</center>
                </submesh>
              </mesh>
            </geometry>
          </visual>
          <collision name='collision'>
            <pose>0 0 0 3.14159 1.57079 3.14159</pose>
            <geometry>
              <sphere>
                <radius>0.31265</radius>
              </sphere>
            </geometry>
            <surface>
              <friction>
                <ode>
                  <mu>1.1</mu>
                  <mu2>1.1</mu2>
                  <slip1>0</slip1>
                  <slip2>0</slip2>
                </ode>
                <torsional>
                  <ode/>
                </torsional>
              </friction>
              <contact>
                <ode>
                  <min_depth>0.001</min_depth>
                  <kp>1e+09</kp>
                </ode>
              </contact>
              <bounce/>
            </surface>
            <max_contacts>10</max_contacts>
          </collision>
          <self_collide>0</self_collide>
          <enable_wind>0</enable_wind>
          <kinematic>0</kinematic>
        </link>
        <joint name='front_left_combined_joint' type='universal'>
          <pose>0 0 0 -0.087266 0 0</pose>
          <child>front_left_wheel</child>
          <parent>chassis</parent>
          <axis>
            <xyz>0 0 1</xyz>
            <limit>
              <lower>-0.8727</lower>
              <upper>0.8727</upper>
            </limit>
            <dynamics>
              <spring_reference>0</spring_reference>
              <spring_stiffness>0</spring_stiffness>
            </dynamics>
          </axis>
          <axis2>
            <xyz>1 0 0</xyz>
            <dynamics>
              <friction>18.0474</friction>
              <spring_reference>0</spring_reference>
              <spring_stiffness>0</spring_stiffness>
            </dynamics>
            <limit>
              <upper>1e+16</upper>
              <lower>-1e+16</lower>
            </limit>
          </axis2>
        </joint>
        <joint name='front_right_combined_joint' type='universal'>
          <pose>0 0 0 -0.087266 0 0</pose>
          <child>front_right_wheel</child>
          <parent>chassis</parent>
          <axis>
            <xyz>0 0 1</xyz>
            <limit>
              <lower>-0.8727</lower>
              <upper>0.8727</upper>
            </limit>
            <dynamics>
              <spring_reference>0</spring_reference>
              <spring_stiffness>0</spring_stiffness>
            </dynamics>
          </axis>
          <axis2>
            <xyz>1 0 0</xyz>
            <dynamics>
              <friction>18.0474</friction>
              <spring_reference>0</spring_reference>
              <spring_stiffness>0</spring_stiffness>
            </dynamics>
            <limit>
              <upper>1e+16</upper>
              <lower>-1e+16</lower>
            </limit>
          </axis2>
        </joint>
        <link name='rear_axle'>
          <pose>0 1.45 0.3 0 -0 0</pose>
          <inertial>
            <mass>30</mass>
            <inertia>
              <ixx>0.084375</ixx>
              <ixy>0</ixy>
              <iyy>4.64581</iyy>
              <ixz>0</ixz>
              <iyz>0</iyz>
              <izz>4.64581</izz>
            </inertia>
            <pose>0 0 0 0 -0 0</pose>
          </inertial>
          <visual name='visual'>
            <pose>0 0 0 3.14159 1.57079 3.14159</pose>
            <geometry>
              <cylinder>
                <length>1.357</length>
                <radius>0.075</radius>
              </cylinder>
            </geometry>
            <material>
              <script>
                <name>Gazebo/Grey</name>
                <uri>file://media/materials/scripts/gazebo.material</uri>
              </script>
            </material>
          </visual>
          <self_collide>0</self_collide>
          <enable_wind>0</enable_wind>
          <kinematic>0</kinematic>
        </link>
        <joint name='rear_axle_joint' type='revolute'>
          <child>rear_axle</child>
          <parent>chassis</parent>
          <axis>
            <xyz>0 1 0</xyz>
            <limit>
              <lower>-0.0508906</lower>
              <upper>0.0508906</upper>
            </limit>
            <dynamics>
              <spring_stiffness>20000</spring_stiffness>
              <damping>2000</damping>
              <spring_reference>0</spring_reference>
            </dynamics>
          </axis>
        </joint>
        <joint name='rear_left_wheel_joint' type='revolute'>
          <child>rear_left_wheel</child>
          <parent>rear_axle</parent>
          <axis>
            <xyz>1 0 0</xyz>
            <dynamics>
              <friction>12.0316</friction>
              <spring_reference>0</spring_reference>
              <spring_stiffness>0</spring_stiffness>
            </dynamics>
            <limit>
              <lower>-1e+16</lower>
              <upper>1e+16</upper>
            </limit>
          </axis>
        </joint>
        <joint name='rear_right_wheel_joint' type='revolute'>
          <child>rear_right_wheel</child>
          <parent>rear_axle</parent>
          <axis>
            <xyz>1 0 0</xyz>
            <dynamics>
              <friction>12.0316</friction>
              <spring_reference>0</spring_reference>
              <spring_stiffness>0</spring_stiffness>
            </dynamics>
            <limit>
              <lower>-1e+16</lower>
              <upper>1e+16</upper>
            </limit>
          </axis>
        </joint>
        <joint name='steering_joint' type='revolute'>
          <pose>-0.002 0 0 0 -0 0</pose>
          <parent>chassis</parent>
          <child>steering_wheel</child>
          <axis>
            <xyz expressed_in='__model__'>0 0.964095 0.265556</xyz>
            <limit>
              <lower>-7.85</lower>
              <upper>7.85</upper>
            </limit>
            <dynamics>
              <damping>1</damping>
              <spring_reference>0</spring_reference>
              <spring_stiffness>0</spring_stiffness>
            </dynamics>
          </axis>
          <physics>
            <ode>
              <cfm_damping>1</cfm_damping>
              <limit>
                <cfm>0</cfm>
                <erp>0.2</erp>
              </limit>
            </ode>
          </physics>
        </joint>
      </model>
      <static>0</static>
      <allow_auto_disable>1</allow_auto_disable>
      <pose>395.069 -657.165 0.102394 0 -0 -1.3e-05</pose>
    </model>
    <model name='car_with_inlet_v3'>
      <model name='inlet'>
        <link name='link'>
          <gravity>1</gravity>
          <self_collide>0</self_collide>
          <inertial>
            <mass>0.4</mass>
            <inertia>
              <ixx>0.0004</ixx>
              <iyy>0.0002</iyy>
              <izz>0.0003</izz>
              <ixy>0</ixy>
              <ixz>0</ixz>
              <iyz>0</iyz>
            </inertia>
            <pose>0 0 0 0 -0 0</pose>
          </inertial>
          <visual name='visual'>
            <geometry>
              <mesh>
                <uri>model://inlet/meshes/inlet.dae</uri>
                <scale>1 1 1</scale>
              </mesh>
            </geometry>
            <cast_shadows>0</cast_shadows>
          </visual>
          <collision name='col_bottom'>
            <pose>0 0 -0.03 0 -0 0</pose>
            <geometry>
              <box>
                <size>0.15 0.08 0.06</size>
              </box>
            </geometry>
            <surface>
              <contact>
                <ode/>
              </contact>
              <friction>
                <ode/>
                <torsional>
                  <ode/>
                </torsional>
              </friction>
              <bounce/>
            </surface>
            <max_contacts>10</max_contacts>
          </collision>
          <enable_wind>0</enable_wind>
          <kinematic>0</kinematic>
        </link>
        <pose>0.435144 0.735619 0.388173 0 -0 1.52002</pose>
      </model>
      <model name='prius_hybrid'>
        <pose>-0.480609 -0.757579 -0.401981 0 -0 0</pose>
        <link name='chassis'>
          <inertial>
            <mass>1326</mass>
            <pose>0 -0.266 0.48 0 -0 0</pose>
            <inertia>
              <ixx>2581.13</ixx>
              <ixy>0</ixy>
              <iyy>591.308</iyy>
              <ixz>0</ixz>
              <iyz>0</iyz>
              <izz>2681.95</izz>
            </inertia>
          </inertial>
          <visual name='chassis_visual'>
            <geometry>
              <mesh>
                <uri>model://prius_hybrid/meshes/Hybrid.obj</uri>
                <scale>0.01 0.01 0.01</scale>
                <submesh>
                  <name>Hybrid</name>
                  <center>0</center>
                </submesh>
              </mesh>
            </geometry>
          </visual>
          <visual name='interior_visual'>
            <geometry>
              <mesh>
                <uri>model://prius_hybrid/meshes/Hybrid.obj</uri>
                <scale>0.01 0.01 0.01</scale>
                <submesh>
                  <name>Hybrid_Interior</name>
                  <center>0</center>
                </submesh>
              </mesh>
            </geometry>
          </visual>
          <visual name='windows_visual'>
            <geometry>
              <mesh>
                <uri>model://prius_hybrid/meshes/Hybrid.obj</uri>
                <scale>0.01 0.01 0.01</scale>
                <submesh>
                  <name>Hybrid_Windows</name>
                  <center>0</center>
                </submesh>
              </mesh>
            </geometry>
          </visual>
          <collision name='chassis'>
            <pose>0 0.05 0.625 0 -0 0</pose>
            <geometry>
              <box>
                <size>1.7526 2.1 0.95</size>
              </box>
            </geometry>
            <max_contacts>10</max_contacts>
            <surface>
              <contact>
                <ode/>
              </contact>
              <bounce/>
              <friction>
                <torsional>
                  <ode/>
                </torsional>
                <ode/>
              </friction>
            </surface>
          </collision>
          <collision name='front_bumper'>
            <pose>0 -2 0.458488 0 -0 0</pose>
            <geometry>
              <box>
                <size>1.33728 0.48 0.566691</size>
              </box>
            </geometry>
            <max_contacts>10</max_contacts>
            <surface>
              <contact>
                <ode/>
              </contact>
              <bounce/>
              <friction>
                <torsional>
                  <ode/>
                </torsional>
                <ode/>
              </friction>
            </surface>
          </collision>
          <collision name='hood'>
            <pose>0 -1.90084 0.676305 0.341247 -0 0</pose>
            <geometry>
              <box>
                <size>1.59797 0.493107 0.265468</size>
              </box>
            </geometry>
            <max_contacts>10</max_contacts>
            <surface>
              <contact>
                <ode/>
              </contact>
              <bounce/>
              <friction>
                <torsional>
                  <ode/>
                </torsional>
                <ode/>
              </friction>
            </surface>
          </collision>
          <collision name='windshield'>
            <pose>0 -0.875105 1.03227 0.335476 -0 0</pose>
            <geometry>
              <box>
                <size>1.16838 1.65425 0.272347</size>
              </box>
            </geometry>
            <max_contacts>10</max_contacts>
            <surface>
              <contact>
                <ode/>
              </contact>
              <bounce/>
              <friction>
                <torsional>
                  <ode/>
                </torsional>
                <ode/>
              </friction>
            </surface>
          </collision>
          <collision name='top_front'>
            <pose>0 0.161236 1.38604 0.13503 -0 0</pose>
            <geometry>
              <box>
                <size>1.27915 0.625988 0.171868</size>
              </box>
            </geometry>
            <max_contacts>10</max_contacts>
            <surface>
              <contact>
                <ode/>
              </contact>
              <bounce/>
              <friction>
                <torsional>
                  <ode/>
                </torsional>
                <ode/>
              </friction>
            </surface>
          </collision>
          <collision name='top_rear'>
            <pose>0 0.817696 1.36007 -0.068997 0 0</pose>
            <geometry>
              <box>
                <size>1.28513 0.771189 0.226557</size>
              </box>
            </geometry>
            <max_contacts>10</max_contacts>
            <surface>
              <contact>
                <ode/>
              </contact>
              <bounce/>
              <friction>
                <torsional>
                  <ode/>
                </torsional>
                <ode/>
              </friction>
            </surface>
          </collision>
          <collision name='rear_window'>
            <pose>0 1.64053 1.17513 -0.262017 0 0</pose>
            <geometry>
              <box>
                <size>1.26785 1.11634 0.244286</size>
              </box>
            </geometry>
            <max_contacts>10</max_contacts>
            <surface>
              <contact>
                <ode/>
              </contact>
              <bounce/>
              <friction>
                <torsional>
                  <ode/>
                </torsional>
                <ode/>
              </friction>
            </surface>
          </collision>
          <collision name='trunk'>
            <pose>0 1.63706 0.88818 0 -0 0</pose>
            <geometry>
              <box>
                <size>1.78806 1.13899 0.482746</size>
              </box>
            </geometry>
            <max_contacts>10</max_contacts>
            <surface>
              <contact>
                <ode/>
              </contact>
              <bounce/>
              <friction>
                <torsional>
                  <ode/>
                </torsional>
                <ode/>
              </friction>
            </surface>
          </collision>
          <collision name='back_bumper'>
            <pose>0 2.05445 0.57787 0 -0 0</pose>
            <geometry>
              <box>
                <size>1.78165 0.512093 0.581427</size>
              </box>
            </geometry>
            <max_contacts>10</max_contacts>
            <surface>
              <contact>
                <ode/>
              </contact>
              <bounce/>
              <friction>
                <torsional>
                  <ode/>
                </torsional>
                <ode/>
              </friction>
            </surface>
          </collision>
          <self_collide>0</self_collide>
          <enable_wind>0</enable_wind>
          <kinematic>0</kinematic>
        </link>
        <link name='steering_wheel'>
          <pose>0.357734 -0.627868 0.988243 -1.3021 0 0</pose>
          <inertial>
            <mass>1</mass>
            <inertia>
              <ixx>0.145833</ixx>
              <ixy>0</ixy>
              <ixz>0</ixz>
              <iyy>0.145833</iyy>
              <iyz>0</iyz>
              <izz>0.125</izz>
            </inertia>
            <pose>0 0 0 0 -0 0</pose>
          </inertial>
          <collision name='collision'>
            <geometry>
              <cylinder>
                <radius>0.178172</radius>
                <length>0.041845</length>
              </cylinder>
            </geometry>
            <surface>
              <contact>
                <ode>
                  <min_depth>0.003</min_depth>
                </ode>
              </contact>
              <bounce/>
              <friction>
                <torsional>
                  <ode/>
                </torsional>
                <ode/>
              </friction>
            </surface>
            <max_contacts>10</max_contacts>
          </collision>
          <visual name='visual'>
            <pose>0 0 0 1.3021 -0 0</pose>
            <geometry>
              <mesh>
                <uri>model://prius_hybrid/meshes/Hybrid.obj</uri>
                <scale>0.01 0.01 0.01</scale>
                <submesh>
                  <name>Steering_Wheel</name>
                  <center>1</center>
                </submesh>
              </mesh>
            </geometry>
          </visual>
          <self_collide>0</self_collide>
          <enable_wind>0</enable_wind>
          <kinematic>0</kinematic>
        </link>
        <link name='front_left_wheel'>
          <pose>0.76 -1.41 0.3 0 -0 0</pose>
          <inertial>
            <mass>11</mass>
            <inertia>
              <ixx>0.586312</ixx>
              <ixy>0</ixy>
              <iyy>0.335529</iyy>
              <ixz>0</ixz>
              <iyz>0</iyz>
              <izz>0.335529</izz>
            </inertia>
            <pose>0 0 0 0 -0 0</pose>
          </inertial>
          <visual name='visual'>
            <pose>0.04 0 0 0 -0 0</pose>
            <geometry>
              <mesh>
                <uri>model://prius_hybrid/meshes/Hybrid.obj</uri>
                <scale>0.01 0.01 0.01</scale>
                <submesh>
                  <name>Wheel_Front_Left_</name>
                  <center>1</center>
                </submesh>
              </mesh>
            </geometry>
          </visual>
          <collision name='collision'>
            <pose>0 0 0 3.14159 1.57079 3.14159</pose>
            <geometry>
              <sphere>
                <radius>0.31265</radius>
              </sphere>
            </geometry>
            <surface>
              <friction>
                <ode>
                  <mu>0.9</mu>
                  <mu2>0.9</mu2>
                  <slip1>0</slip1>
                  <slip2>0</slip2>
                </ode>
                <torsional>
                  <ode/>
                </torsional>
              </friction>
              <contact>
                <ode>
                  <min_depth>0.001</min_depth>
                  <kp>1e+09</kp>
                </ode>
              </contact>
              <bounce/>
            </surface>
            <max_contacts>10</max_contacts>
          </collision>
          <self_collide>0</self_collide>
          <enable_wind>0</enable_wind>
          <kinematic>0</kinematic>
        </link>
        <link name='front_right_wheel'>
          <pose>-0.76 -1.41 0.3 0 -0 0</pose>
          <inertial>
            <mass>11</mass>
            <inertia>
              <ixx>0.586312</ixx>
              <ixy>0</ixy>
              <iyy>0.335529</iyy>
              <ixz>0</ixz>
              <iyz>0</iyz>
              <izz>0.335529</izz>
            </inertia>
            <pose>0 0 0 0 -0 0</pose>
          </inertial>
          <visual name='visual'>
            <pose>-0.04 0 0 0 -0 0</pose>
            <pose>0 0 0 0 -0 0</pose>
            <geometry>
              <mesh>
                <uri>model://prius_hybrid/meshes/Hybrid.obj</uri>
                <scale>0.01 0.01 0.01</scale>
                <submesh>
                  <name>Wheel_Front_Right</name>
                  <center>1</center>
                </submesh>
              </mesh>
            </geometry>
          </visual>
          <collision name='collision'>
            <pose>0 0 0 3.14159 1.57079 3.14159</pose>
            <geometry>
              <sphere>
                <radius>0.31265</radius>
              </sphere>
            </geometry>
            <surface>
              <friction>
                <ode>
                  <mu>0.9</mu>
                  <mu2>0.9</mu2>
                  <slip1>0</slip1>
                  <slip2>0</slip2>
                </ode>
                <torsional>
                  <ode/>
                </torsional>
              </friction>
              <contact>
                <ode>
                  <min_depth>0.001</min_depth>
                  <kp>1e+09</kp>
                </ode>
              </contact>
              <bounce/>
            </surface>
            <max_contacts>10</max_contacts>
          </collision>
          <self_collide>0</self_collide>
          <enable_wind>0</enable_wind>
          <kinematic>0</kinematic>
        </link>
        <link name='rear_left_wheel'>
          <pose>0.786 1.45 0.3 0 -0 0</pose>
          <inertial>
            <mass>11</mass>
            <inertia>
              <ixx>0.586312</ixx>
              <ixy>0</ixy>
              <iyy>0.335529</iyy>
              <ixz>0</ixz>
              <iyz>0</iyz>
              <izz>0.335529</izz>
            </inertia>
            <pose>0 0 0 0 -0 0</pose>
          </inertial>
          <visual name='visual'>
            <pose>0.04 0 0 0 -0 0</pose>
            <geometry>
              <mesh>
                <uri>model://prius_hybrid/meshes/Hybrid.obj</uri>
                <scale>0.01 0.01 0.01</scale>
                <submesh>
                  <name>Wheel_Front_Left_</name>
                  <center>1</center>
                </submesh>
              </mesh>
            </geometry>
          </visual>
          <collision name='collision'>
            <pose>0 0 0 3.14159 1.57079 3.14159</pose>
            <geometry>
              <sphere>
                <radius>0.31265</radius>
              </sphere>
            </geometry>
            <surface>
              <friction>
                <ode>
                  <mu>1.1</mu>
                  <mu2>1.1</mu2>
                  <slip1>0</slip1>
                  <slip2>0</slip2>
                </ode>
                <torsional>
                  <ode/>
                </torsional>
              </friction>
              <contact>
                <ode>
                  <min_depth>0.001</min_depth>
                  <kp>1e+09</kp>
                </ode>
              </contact>
              <bounce/>
            </surface>
            <max_contacts>10</max_contacts>
          </collision>
          <self_collide>0</self_collide>
          <enable_wind>0</enable_wind>
          <kinematic>0</kinematic>
        </link>
        <link name='rear_right_wheel'>
          <pose>-0.786 1.45 0.3 0 -0 0</pose>
          <inertial>
            <mass>11</mass>
            <inertia>
              <ixx>0.586312</ixx>
              <ixy>0</ixy>
              <iyy>0.335529</iyy>
              <ixz>0</ixz>
              <iyz>0</iyz>
              <izz>0.335529</izz>
            </inertia>
            <pose>0 0 0 0 -0 0</pose>
          </inertial>
          <visual name='visual'>
            <pose>-0.04 0 0 0 -0 0</pose>
            <geometry>
              <mesh>
                <uri>model://prius_hybrid/meshes/Hybrid.obj</uri>
                <scale>0.01 0.01 0.01</scale>
                <submesh>
                  <name>Wheel_Front_Right</name>
                  <center>1</center>
                </submesh>
              </mesh>
            </geometry>
          </visual>
          <collision name='collision'>
            <pose>0 0 0 3.14159 1.57079 3.14159</pose>
            <geometry>
              <sphere>
                <radius>0.31265</radius>
              </sphere>
            </geometry>
            <surface>
              <friction>
                <ode>
                  <mu>1.1</mu>
                  <mu2>1.1</mu2>
                  <slip1>0</slip1>
                  <slip2>0</slip2>
                </ode>
                <torsional>
                  <ode/>
                </torsional>
              </friction>
              <contact>
                <ode>
                  <min_depth>0.001</min_depth>
                  <kp>1e+09</kp>
                </ode>
              </contact>
              <bounce/>
            </surface>
            <max_contacts>10</max_contacts>
          </collision>
          <self_collide>0</self_collide>
          <enable_wind>0</enable_wind>
          <kinematic>0</kinematic>
        </link>
        <joint name='front_left_combined_joint' type='universal'>
          <pose>0 0 0 -0.087266 0 0</pose>
          <child>front_left_wheel</child>
          <parent>chassis</parent>
          <axis>
            <xyz>0 0 1</xyz>
            <limit>
              <lower>-0.8727</lower>
              <upper>0.8727</upper>
            </limit>
            <dynamics>
              <spring_reference>0</spring_reference>
              <spring_stiffness>0</spring_stiffness>
            </dynamics>
          </axis>
          <axis2>
            <xyz>1 0 0</xyz>
            <dynamics>
              <friction>18.0474</friction>
              <spring_reference>0</spring_reference>
              <spring_stiffness>0</spring_stiffness>
            </dynamics>
            <limit>
              <upper>1e+16</upper>
              <lower>-1e+16</lower>
            </limit>
          </axis2>
        </joint>
        <joint name='front_right_combined_joint' type='universal'>
          <pose>0 0 0 -0.087266 0 0</pose>
          <child>front_right_wheel</child>
          <parent>chassis</parent>
          <axis>
            <xyz>0 0 1</xyz>
            <limit>
              <lower>-0.8727</lower>
              <upper>0.8727</upper>
            </limit>
            <dynamics>
              <spring_reference>0</spring_reference>
              <spring_stiffness>0</spring_stiffness>
            </dynamics>
          </axis>
          <axis2>
            <xyz>1 0 0</xyz>
            <dynamics>
              <friction>18.0474</friction>
              <spring_reference>0</spring_reference>
              <spring_stiffness>0</spring_stiffness>
            </dynamics>
            <limit>
              <upper>1e+16</upper>
              <lower>-1e+16</lower>
            </limit>
          </axis2>
        </joint>
        <link name='rear_axle'>
          <pose>0 1.45 0.3 0 -0 0</pose>
          <inertial>
            <mass>30</mass>
            <inertia>
              <ixx>0.084375</ixx>
              <ixy>0</ixy>
              <iyy>4.64581</iyy>
              <ixz>0</ixz>
              <iyz>0</iyz>
              <izz>4.64581</izz>
            </inertia>
            <pose>0 0 0 0 -0 0</pose>
          </inertial>
          <visual name='visual'>
            <pose>0 0 0 3.14159 1.57079 3.14159</pose>
            <geometry>
              <cylinder>
                <length>1.357</length>
                <radius>0.075</radius>
              </cylinder>
            </geometry>
            <material>
              <script>
                <name>Gazebo/Grey</name>
                <uri>file://media/materials/scripts/gazebo.material</uri>
              </script>
            </material>
          </visual>
          <self_collide>0</self_collide>
          <enable_wind>0</enable_wind>
          <kinematic>0</kinematic>
        </link>
        <joint name='rear_axle_joint' type='revolute'>
          <child>rear_axle</child>
          <parent>chassis</parent>
          <axis>
            <xyz>0 1 0</xyz>
            <limit>
              <lower>-0.0508906</lower>
              <upper>0.0508906</upper>
            </limit>
            <dynamics>
              <spring_stiffness>20000</spring_stiffness>
              <damping>2000</damping>
              <spring_reference>0</spring_reference>
            </dynamics>
          </axis>
        </joint>
        <joint name='rear_left_wheel_joint' type='revolute'>
          <child>rear_left_wheel</child>
          <parent>rear_axle</parent>
          <axis>
            <xyz>1 0 0</xyz>
            <dynamics>
              <friction>12.0316</friction>
              <spring_reference>0</spring_reference>
              <spring_stiffness>0</spring_stiffness>
            </dynamics>
            <limit>
              <lower>-1e+16</lower>
              <upper>1e+16</upper>
            </limit>
          </axis>
        </joint>
        <joint name='rear_right_wheel_joint' type='revolute'>
          <child>rear_right_wheel</child>
          <parent>rear_axle</parent>
          <axis>
            <xyz>1 0 0</xyz>
            <dynamics>
              <friction>12.0316</friction>
              <spring_reference>0</spring_reference>
              <spring_stiffness>0</spring_stiffness>
            </dynamics>
            <limit>
              <lower>-1e+16</lower>
              <upper>1e+16</upper>
            </limit>
          </axis>
        </joint>
        <joint name='steering_joint' type='revolute'>
          <pose>-0.002 0 0 0 -0 0</pose>
          <parent>chassis</parent>
          <child>steering_wheel</child>
          <axis>
            <xyz expressed_in='__model__'>0 0.964095 0.265556</xyz>
            <limit>
              <lower>-7.85</lower>
              <upper>7.85</upper>
            </limit>
            <dynamics>
              <damping>1</damping>
              <spring_reference>0</spring_reference>
              <spring_stiffness>0</spring_stiffness>
            </dynamics>
          </axis>
          <physics>
            <ode>
              <cfm_damping>1</cfm_damping>
              <limit>
                <cfm>0</cfm>
                <erp>0.2</erp>
              </limit>
            </ode>
          </physics>
        </joint>
      </model>
      <joint name='chassis_JOINT_0' type='fixed'>
        <parent>prius_hybrid::chassis</parent>
        <child>inlet::link</child>
        <pose>0 0 0 0 -0 0</pose>
        <physics>
          <ode>
            <limit>
              <cfm>0</cfm>
              <erp>0.2</erp>
            </limit>
            <suspension>
              <cfm>0</cfm>
              <erp>0.2</erp>
            </suspension>
          </ode>
        </physics>
      </joint>
      <static>0</static>
      <allow_auto_disable>1</allow_auto_disable>
      <pose>-0.517888 1.38986 0.401051 0.000276 0.004322 -1.50714</pose>
    </model>
  </world>
</sdf>
